Watching for file changes with StatReloader
Not Found: /
[03/Dec/2020 12:02:51] "GET / HTTP/1.1" 404 2584
Not Found: /favicon.ico
[03/Dec/2020 12:02:51] "GET /favicon.ico HTTP/1.1" 404 2635
[03/Dec/2020 12:02:56] "GET /get_crt HTTP/1.1" 200 362
[03/Dec/2020 15:18:15] "GET /api/vocabulary?text=rubidium HTTP/1.1" 200 25
[07/Dec/2020 14:39:17] "GET /api/vocabulary?text=extravagantly HTTP/1.1" 200 25
[07/Dec/2020 15:13:58] "GET /api/vocabulary?text=indelibly HTTP/1.1" 200 25
[07/Dec/2020 15:21:30] "GET /api/vocabulary?text=ostensibly HTTP/1.1" 200 25
[07/Dec/2020 15:26:41] "GET /api/vocabulary?text=caveat HTTP/1.1" 200 25
[07/Dec/2020 15:34:42] "GET /api/vocabulary?text=Matryoshka HTTP/1.1" 200 25
[07/Dec/2020 15:46:44] "GET /api/vocabulary?text=ginormous HTTP/1.1" 200 25
[08/Dec/2020 12:23:53] "GET /api/vocabulary?text=obfuscate HTTP/1.1" 200 25
[09/Dec/2020 17:01:16] "GET /image HTTP/1.1" 200 523
[09/Dec/2020 17:01:17] "GET /static/res/image/20201112124406.jpeg HTTP/1.1" 200 34664
[09/Dec/2020 17:01:17] "GET /static/res/image/20201112124337.jpeg HTTP/1.1" 200 143305
[09/Dec/2020 17:01:17] "GET /static/res/image/20201112124700.jpg HTTP/1.1" 200 3843
Not Found: /favicon.ico
[09/Dec/2020 17:01:17] "GET /favicon.ico HTTP/1.1" 404 2635
[09/Dec/2020 17:01:25] "GET /static/res/files HTTP/1.1" 404 1650
[09/Dec/2020 17:01:34] "GET /static/res/files/genlic.py HTTP/1.1" 200 6740
[14/Dec/2020 12:50:29] "GET /api/vocabulary?text=porcelain HTTP/1.1" 200 25
[14/Dec/2020 13:19:47] "GET /api/vocabulary?text=palimpsest HTTP/1.1" 200 25
[15/Dec/2020 09:46:58] "GET /api/vocabulary?text=fissures HTTP/1.1" 200 25
[15/Dec/2020 09:47:16] "GET /api/vocabulary?text=acrid HTTP/1.1" 200 25
Watching for file changes with StatReloader
[30/Dec/2020 13:15:46] "GET /api/vocabulary?text=mortgage HTTP/1.1" 200 25
[30/Dec/2020 14:51:51] "GET /api/vocabulary?text=crescent HTTP/1.1" 200 25
[05/Jan/2021 10:18:07] "GET /api/vocabulary?text=rehearsed HTTP/1.1" 200 25
[19/Jan/2021 15:40:31] "GET /api/image HTTP/1.1" 200 15
Not Found: /favicon.ico
[19/Jan/2021 15:40:31] "GET /favicon.ico HTTP/1.1" 404 2744
[19/Jan/2021 15:40:36] "GET /api/image HTTP/1.1" 200 15
[19/Jan/2021 15:40:39] "GET /image HTTP/1.1" 200 523
[19/Jan/2021 15:40:39] "GET /static/res/image/20201112124700.jpg HTTP/1.1" 200 3843
[19/Jan/2021 15:40:39] "GET /static/res/image/20201112124406.jpeg HTTP/1.1" 200 34664
[19/Jan/2021 15:40:39] "GET /static/res/image/20201112124337.jpeg HTTP/1.1" 200 143305
[19/Jan/2021 15:40:42] "GET /api/image HTTP/1.1" 200 15
[19/Jan/2021 15:40:44] "GET /vocabulary HTTP/1.1" 200 5000
[19/Jan/2021 15:40:58] "GET /api/vocabulary HTTP/1.1" 200 15
[19/Jan/2021 15:41:06] "GET /api/ocr HTTP/1.1" 200 15
[20/Jan/2021 09:46:42] "GET /api/vocabulary?text=garlic HTTP/1.1" 200 25
[20/Jan/2021 09:46:44] "GET /api/vocabulary?text=clove HTTP/1.1" 200 25
[20/Jan/2021 09:46:47] "GET /image HTTP/1.1" 200 523
Not Found: /favicon.ico
[20/Jan/2021 09:46:48] "GET /favicon.ico HTTP/1.1" 404 2744
[20/Jan/2021 09:47:22] "GET /api/vocabulary?text=turmeric HTTP/1.1" 200 25
[20/Jan/2021 10:08:37] "GET /api/vocabulary?text=labyrinthine HTTP/1.1" 200 25
[21/Jan/2021 11:08:25] "GET /api/vocabulary?text=scion HTTP/1.1" 200 25
[21/Jan/2021 11:08:43] "GET /api/vocabulary?text=chloroplasts HTTP/1.1" 200 25
[21/Jan/2021 11:15:11] "GET /api/vocabulary?text=callus HTTP/1.1" 200 25
[21/Jan/2021 11:18:30] "GET /api/vocabulary?text=protrusions HTTP/1.1" 200 25
[25/Jan/2021 14:07:05] "GET /api/vocabulary?text=epiphany HTTP/1.1" 200 25
 * Debugger is active!

 * Debugger PIN: 139-081-676

/usr/local/lib/python3.6/dist-packages/urllib3/connectionpool.py:1020: InsecureRequestWarning: Unverified HTTPS request is being made to host '192.168.0.207'. Adding certificate verification is strongly advised. See: https://urllib3.readthedocs.io/en/latest/advanced-usage.html#ssl-warnings
  InsecureRequestWarning,
192.168.0.2 - - [10/Mar/2021 15:53:47] "GET /api/bhpwd?user=&host=192.168.0.207 HTTP/1.1" 200 -

/usr/local/lib/python3.6/dist-packages/urllib3/connectionpool.py:1020: InsecureRequestWarning: Unverified HTTPS request is being made to host '192.168.0.207'. Adding certificate verification is strongly advised. See: https://urllib3.readthedocs.io/en/latest/advanced-usage.html#ssl-warnings
  InsecureRequestWarning,
192.168.0.2 - - [10/Mar/2021 15:53:58] "GET /api/bhpwd?user=admin&host=192.168.0.207 HTTP/1.1" 200 -

/usr/local/lib/python3.6/dist-packages/urllib3/connectionpool.py:1020: InsecureRequestWarning: Unverified HTTPS request is being made to host '192.168.0.207'. Adding certificate verification is strongly advised. See: https://urllib3.readthedocs.io/en/latest/advanced-usage.html#ssl-warnings
  InsecureRequestWarning,
192.168.0.2 - - [10/Mar/2021 15:56:51] "GET /api/bhpwd?user=admin&host=192.168.0.207 HTTP/1.1" 200 -

/usr/local/lib/python3.6/dist-packages/urllib3/connectionpool.py:1020: InsecureRequestWarning: Unverified HTTPS request is being made to host '192.168.0.207'. Adding certificate verification is strongly advised. See: https://urllib3.readthedocs.io/en/latest/advanced-usage.html#ssl-warnings
  InsecureRequestWarning,
192.168.0.2 - - [10/Mar/2021 15:57:28] "GET /api/bhpwd?user=demo&host=192.168.0.207 HTTP/1.1" 200 -

/usr/local/lib/python3.6/dist-packages/urllib3/connectionpool.py:1020: InsecureRequestWarning: Unverified HTTPS request is being made to host '192.168.0.207'. Adding certificate verification is strongly advised. See: https://urllib3.readthedocs.io/en/latest/advanced-usage.html#ssl-warnings
  InsecureRequestWarning,
192.168.0.2 - - [10/Mar/2021 15:58:49] "GET /api/bhpwd?user=&host=192.168.0.207 HTTP/1.1" 200 -

/usr/local/lib/python3.6/dist-packages/urllib3/connectionpool.py:1020: InsecureRequestWarning: Unverified HTTPS request is being made to host '192.168.0.207'. Adding certificate verification is strongly advised. See: https://urllib3.readthedocs.io/en/latest/advanced-usage.html#ssl-warnings
  InsecureRequestWarning,
192.168.0.2 - - [10/Mar/2021 15:59:20] "GET /api/bhpwd?user=&host=192.168.0.207 HTTP/1.1" 200 -

/usr/local/lib/python3.6/dist-packages/urllib3/connectionpool.py:1020: InsecureRequestWarning: Unverified HTTPS request is being made to host '192.168.0.207'. Adding certificate verification is strongly advised. See: https://urllib3.readthedocs.io/en/latest/advanced-usage.html#ssl-warnings
  InsecureRequestWarning,
192.168.0.2 - - [10/Mar/2021 15:59:59] "GET /api/bhpwd?user=&host=192.168.0.207 HTTP/1.1" 200 -

/usr/local/lib/python3.6/dist-packages/urllib3/connectionpool.py:1020: InsecureRequestWarning: Unverified HTTPS request is being made to host '192.168.0.207'. Adding certificate verification is strongly advised. See: https://urllib3.readthedocs.io/en/latest/advanced-usage.html#ssl-warnings
  InsecureRequestWarning,
192.168.0.2 - - [10/Mar/2021 16:00:02] "GET /api/bhpwd?user=admin&host=192.168.0.207 HTTP/1.1" 200 -

/usr/local/lib/python3.6/dist-packages/urllib3/connectionpool.py:1020: InsecureRequestWarning: Unverified HTTPS request is being made to host '192.168.0.207'. Adding certificate verification is strongly advised. See: https://urllib3.readthedocs.io/en/latest/advanced-usage.html#ssl-warnings
  InsecureRequestWarning,
192.168.0.2 - - [10/Mar/2021 17:07:43] "GET /api/bhpwd?user=admin&host=192.168.0.207 HTTP/1.1" 200 -

/usr/local/lib/python3.6/dist-packages/urllib3/connectionpool.py:1020: InsecureRequestWarning: Unverified HTTPS request is being made to host '192.168.0.207'. Adding certificate verification is strongly advised. See: https://urllib3.readthedocs.io/en/latest/advanced-usage.html#ssl-warnings
  InsecureRequestWarning,
192.168.0.2 - - [11/Mar/2021 09:24:44] "GET /api/bhpwd?user=admin&host=192.168.0.207 HTTP/1.1" 200 -

/usr/local/lib/python3.6/dist-packages/urllib3/connectionpool.py:1020: InsecureRequestWarning: Unverified HTTPS request is being made to host '192.168.0.207'. Adding certificate verification is strongly advised. See: https://urllib3.readthedocs.io/en/latest/advanced-usage.html#ssl-warnings
  InsecureRequestWarning,
192.168.0.2 - - [11/Mar/2021 09:26:09] "GET /api/bhpwd?user=demo&host=192.168.0.207 HTTP/1.1" 200 -

/usr/local/lib/python3.6/dist-packages/urllib3/connectionpool.py:1020: InsecureRequestWarning: Unverified HTTPS request is being made to host '192.168.0.207'. Adding certificate verification is strongly advised. See: https://urllib3.readthedocs.io/en/latest/advanced-usage.html#ssl-warnings
  InsecureRequestWarning,
192.168.0.2 - - [11/Mar/2021 09:28:25] "GET /api/bhpwd?user=demo&host=192.168.0.207 HTTP/1.1" 200 -

/usr/local/lib/python3.6/dist-packages/urllib3/connectionpool.py:1020: InsecureRequestWarning: Unverified HTTPS request is being made to host '192.168.0.207'. Adding certificate verification is strongly advised. See: https://urllib3.readthedocs.io/en/latest/advanced-usage.html#ssl-warnings
  InsecureRequestWarning,
192.168.0.2 - - [11/Mar/2021 09:29:51] "GET /api/bhpwd?user=demo&host=192.168.0.207 HTTP/1.1" 200 -

/usr/local/lib/python3.6/dist-packages/urllib3/connectionpool.py:1020: InsecureRequestWarning: Unverified HTTPS request is being made to host '192.168.0.207'. Adding certificate verification is strongly advised. See: https://urllib3.readthedocs.io/en/latest/advanced-usage.html#ssl-warnings
  InsecureRequestWarning,
192.168.0.2 - - [11/Mar/2021 09:32:25] "GET /api/bhpwd?user=admin&host=192.168.0.207 HTTP/1.1" 200 -

/usr/local/lib/python3.6/dist-packages/urllib3/connectionpool.py:1020: InsecureRequestWarning: Unverified HTTPS request is being made to host '192.168.0.207'. Adding certificate verification is strongly advised. See: https://urllib3.readthedocs.io/en/latest/advanced-usage.html#ssl-warnings
  InsecureRequestWarning,
192.168.0.2 - - [11/Mar/2021 09:49:09] "GET /api/bhpwd?user=&host=192.168.0.207 HTTP/1.1" 200 -

/usr/local/lib/python3.6/dist-packages/urllib3/connectionpool.py:1020: InsecureRequestWarning: Unverified HTTPS request is being made to host '192.168.0.207'. Adding certificate verification is strongly advised. See: https://urllib3.readthedocs.io/en/latest/advanced-usage.html#ssl-warnings
  InsecureRequestWarning,
192.168.0.2 - - [11/Mar/2021 09:50:15] "GET /api/bhpwd?user=admin&host=192.168.0.207 HTTP/1.1" 200 -

/usr/local/lib/python3.6/dist-packages/urllib3/connectionpool.py:1020: InsecureRequestWarning: Unverified HTTPS request is being made to host '192.168.0.207'. Adding certificate verification is strongly advised. See: https://urllib3.readthedocs.io/en/latest/advanced-usage.html#ssl-warnings
  InsecureRequestWarning,
192.168.0.2 - - [11/Mar/2021 10:10:18] "GET /api/bhpwd?user=admin&host=192.168.0.207 HTTP/1.1" 200 -

/usr/local/lib/python3.6/dist-packages/urllib3/connectionpool.py:1020: InsecureRequestWarning: Unverified HTTPS request is being made to host '192.168.0.207'. Adding certificate verification is strongly advised. See: https://urllib3.readthedocs.io/en/latest/advanced-usage.html#ssl-warnings
  InsecureRequestWarning,
192.168.0.2 - - [11/Mar/2021 10:19:17] "GET /api/bhpwd?user=admin&host=192.168.0.207 HTTP/1.1" 200 -

/usr/local/lib/python3.6/dist-packages/urllib3/connectionpool.py:1020: InsecureRequestWarning: Unverified HTTPS request is being made to host '192.168.0.207'. Adding certificate verification is strongly advised. See: https://urllib3.readthedocs.io/en/latest/advanced-usage.html#ssl-warnings
  InsecureRequestWarning,
192.168.0.2 - - [11/Mar/2021 10:56:46] "GET /api/bhpwd?user=&host=192.168.0.207 HTTP/1.1" 200 -

/usr/local/lib/python3.6/dist-packages/urllib3/connectionpool.py:1020: InsecureRequestWarning: Unverified HTTPS request is being made to host '192.168.0.196'. Adding certificate verification is strongly advised. See: https://urllib3.readthedocs.io/en/latest/advanced-usage.html#ssl-warnings
  InsecureRequestWarning,
192.168.0.2 - - [11/Mar/2021 11:24:39] "GET /api/bhpwd?user=admin&host=192.168.0.196 HTTP/1.1" 200 -

/usr/local/lib/python3.6/dist-packages/urllib3/connectionpool.py:1020: InsecureRequestWarning: Unverified HTTPS request is being made to host '192.168.0.196'. Adding certificate verification is strongly advised. See: https://urllib3.readthedocs.io/en/latest/advanced-usage.html#ssl-warnings
  InsecureRequestWarning,
192.168.0.2 - - [11/Mar/2021 11:25:31] "GET /api/bhpwd?user=admin&host=192.168.0.196 HTTP/1.1" 200 -

/usr/local/lib/python3.6/dist-packages/urllib3/connectionpool.py:1020: InsecureRequestWarning: Unverified HTTPS request is being made to host '192.168.0.196'. Adding certificate verification is strongly advised. See: https://urllib3.readthedocs.io/en/latest/advanced-usage.html#ssl-warnings
  InsecureRequestWarning,
192.168.0.2 - - [11/Mar/2021 11:28:21] "GET /api/bhpwd?user=admin&host=192.168.0.196 HTTP/1.1" 200 -

/usr/local/lib/python3.6/dist-packages/urllib3/connectionpool.py:1020: InsecureRequestWarning: Unverified HTTPS request is being made to host '192.168.0.196'. Adding certificate verification is strongly advised. See: https://urllib3.readthedocs.io/en/latest/advanced-usage.html#ssl-warnings
  InsecureRequestWarning,
192.168.0.2 - - [11/Mar/2021 11:33:50] "GET /api/bhpwd?user=admin&host=192.168.0.196 HTTP/1.1" 200 -

/usr/local/lib/python3.6/dist-packages/urllib3/connectionpool.py:1020: InsecureRequestWarning: Unverified HTTPS request is being made to host '192.168.0.196'. Adding certificate verification is strongly advised. See: https://urllib3.readthedocs.io/en/latest/advanced-usage.html#ssl-warnings
  InsecureRequestWarning,
192.168.0.2 - - [11/Mar/2021 11:36:33] "GET /api/bhpwd?user=admin&host=192.168.0.196 HTTP/1.1" 200 -

/usr/local/lib/python3.6/dist-packages/urllib3/connectionpool.py:1020: InsecureRequestWarning: Unverified HTTPS request is being made to host '192.168.0.196'. Adding certificate verification is strongly advised. See: https://urllib3.readthedocs.io/en/latest/advanced-usage.html#ssl-warnings
  InsecureRequestWarning,
192.168.0.2 - - [11/Mar/2021 11:38:08] "GET /api/bhpwd?user=admin&host=192.168.0.196 HTTP/1.1" 200 -

/usr/local/lib/python3.6/dist-packages/urllib3/connectionpool.py:1020: InsecureRequestWarning: Unverified HTTPS request is being made to host '192.168.0.196'. Adding certificate verification is strongly advised. See: https://urllib3.readthedocs.io/en/latest/advanced-usage.html#ssl-warnings
  InsecureRequestWarning,
192.168.0.2 - - [11/Mar/2021 11:40:35] "GET /api/bhpwd?user=admin&host=192.168.0.196 HTTP/1.1" 200 -

/usr/local/lib/python3.6/dist-packages/urllib3/connectionpool.py:1020: InsecureRequestWarning: Unverified HTTPS request is being made to host '192.168.0.196'. Adding certificate verification is strongly advised. See: https://urllib3.readthedocs.io/en/latest/advanced-usage.html#ssl-warnings
  InsecureRequestWarning,
192.168.0.2 - - [11/Mar/2021 11:42:47] "GET /api/bhpwd?user=admin&host=192.168.0.196 HTTP/1.1" 200 -

/usr/local/lib/python3.6/dist-packages/urllib3/connectionpool.py:1020: InsecureRequestWarning: Unverified HTTPS request is being made to host '192.168.0.196'. Adding certificate verification is strongly advised. See: https://urllib3.readthedocs.io/en/latest/advanced-usage.html#ssl-warnings
  InsecureRequestWarning,
192.168.0.2 - - [11/Mar/2021 11:43:22] "GET /api/bhpwd?user=admin&host=192.168.0.196 HTTP/1.1" 200 -

/usr/local/lib/python3.6/dist-packages/urllib3/connectionpool.py:1020: InsecureRequestWarning: Unverified HTTPS request is being made to host '192.168.0.207'. Adding certificate verification is strongly advised. See: https://urllib3.readthedocs.io/en/latest/advanced-usage.html#ssl-warnings
  InsecureRequestWarning,
192.168.0.2 - - [11/Mar/2021 11:54:51] "GET /api/bhpwd?user=&host=192.168.0.207 HTTP/1.1" 200 -

/usr/local/lib/python3.6/dist-packages/urllib3/connectionpool.py:1020: InsecureRequestWarning: Unverified HTTPS request is being made to host '192.168.0.207'. Adding certificate verification is strongly advised. See: https://urllib3.readthedocs.io/en/latest/advanced-usage.html#ssl-warnings
  InsecureRequestWarning,
192.168.0.2 - - [11/Mar/2021 11:54:55] "GET /api/bhpwd?user=admin&host=192.168.0.207 HTTP/1.1" 200 -

/usr/local/lib/python3.6/dist-packages/urllib3/connectionpool.py:1020: InsecureRequestWarning: Unverified HTTPS request is being made to host '192.168.0.207'. Adding certificate verification is strongly advised. See: https://urllib3.readthedocs.io/en/latest/advanced-usage.html#ssl-warnings
  InsecureRequestWarning,
192.168.0.2 - - [11/Mar/2021 11:58:18] "GET /api/bhpwd?user=&host=192.168.0.207 HTTP/1.1" 200 -

/usr/local/lib/python3.6/dist-packages/urllib3/connectionpool.py:1020: InsecureRequestWarning: Unverified HTTPS request is being made to host '192.168.0.207'. Adding certificate verification is strongly advised. See: https://urllib3.readthedocs.io/en/latest/advanced-usage.html#ssl-warnings
  InsecureRequestWarning,
192.168.0.2 - - [12/Mar/2021 09:26:11] "GET /api/bhpwd?user=admin&host=192.168.0.207 HTTP/1.1" 200 -

/usr/local/lib/python3.6/dist-packages/urllib3/connectionpool.py:1020: InsecureRequestWarning: Unverified HTTPS request is being made to host '192.168.0.207'. Adding certificate verification is strongly advised. See: https://urllib3.readthedocs.io/en/latest/advanced-usage.html#ssl-warnings
  InsecureRequestWarning,
192.168.0.2 - - [12/Mar/2021 09:28:30] "GET /api/bhpwd?user=auditor&host=192.168.0.207 HTTP/1.1" 200 -

/usr/local/lib/python3.6/dist-packages/urllib3/connectionpool.py:1020: InsecureRequestWarning: Unverified HTTPS request is being made to host '192.168.0.207'. Adding certificate verification is strongly advised. See: https://urllib3.readthedocs.io/en/latest/advanced-usage.html#ssl-warnings
  InsecureRequestWarning,
192.168.0.2 - - [12/Mar/2021 09:29:05] "GET /api/bhpwd?user=demo&host=192.168.0.207 HTTP/1.1" 200 -

/usr/local/lib/python3.6/dist-packages/urllib3/connectionpool.py:1020: InsecureRequestWarning: Unverified HTTPS request is being made to host '192.168.0.207'. Adding certificate verification is strongly advised. See: https://urllib3.readthedocs.io/en/latest/advanced-usage.html#ssl-warnings
  InsecureRequestWarning,
192.168.0.2 - - [12/Mar/2021 10:17:24] "GET /api/bhpwd?user=&host=192.168.0.207 HTTP/1.1" 200 -

/usr/local/lib/python3.6/dist-packages/urllib3/connectionpool.py:1020: InsecureRequestWarning: Unverified HTTPS request is being made to host '192.168.0.207'. Adding certificate verification is strongly advised. See: https://urllib3.readthedocs.io/en/latest/advanced-usage.html#ssl-warnings
  InsecureRequestWarning,
192.168.0.2 - - [12/Mar/2021 10:18:51] "GET /api/bhpwd?user=&host=192.168.0.207 HTTP/1.1" 200 -

Not Found: /favicon.ico
192.168.0.2 - - [12/Mar/2021 10:18:51] "GET /favicon.ico HTTP/1.1" 404 -

/usr/local/lib/python3.6/dist-packages/urllib3/connectionpool.py:1020: InsecureRequestWarning: Unverified HTTPS request is being made to host '192.168.0.207'. Adding certificate verification is strongly advised. See: https://urllib3.readthedocs.io/en/latest/advanced-usage.html#ssl-warnings
  InsecureRequestWarning,
192.168.0.2 - - [12/Mar/2021 10:18:54] "GET /api/bhpwd?user=&host=192.168.0.207 HTTP/1.1" 200 -

/usr/local/lib/python3.6/dist-packages/urllib3/connectionpool.py:1020: InsecureRequestWarning: Unverified HTTPS request is being made to host '192.168.0.207'. Adding certificate verification is strongly advised. See: https://urllib3.readthedocs.io/en/latest/advanced-usage.html#ssl-warnings
  InsecureRequestWarning,
192.168.0.2 - - [12/Mar/2021 10:19:19] "GET /api/bhpwd?user=admin&host=192.168.0.207 HTTP/1.1" 200 -

Not Found: /favicon.ico
192.168.0.2 - - [12/Mar/2021 10:19:19] "GET /favicon.ico HTTP/1.1" 404 -

/usr/local/lib/python3.6/dist-packages/urllib3/connectionpool.py:1020: InsecureRequestWarning: Unverified HTTPS request is being made to host '192.168.0.207'. Adding certificate verification is strongly advised. See: https://urllib3.readthedocs.io/en/latest/advanced-usage.html#ssl-warnings
  InsecureRequestWarning,
192.168.0.2 - - [12/Mar/2021 10:19:21] "GET /api/bhpwd?user=admin&host=192.168.0.207 HTTP/1.1" 200 -

/usr/local/lib/python3.6/dist-packages/urllib3/connectionpool.py:1020: InsecureRequestWarning: Unverified HTTPS request is being made to host '192.168.0.207'. Adding certificate verification is strongly advised. See: https://urllib3.readthedocs.io/en/latest/advanced-usage.html#ssl-warnings
  InsecureRequestWarning,
192.168.0.2 - - [12/Mar/2021 10:19:27] "GET /api/bhpwd?user=admin&host=192.168.0.207 HTTP/1.1" 200 -

/usr/local/lib/python3.6/dist-packages/urllib3/connectionpool.py:1020: InsecureRequestWarning: Unverified HTTPS request is being made to host '192.168.0.207'. Adding certificate verification is strongly advised. See: https://urllib3.readthedocs.io/en/latest/advanced-usage.html#ssl-warnings
  InsecureRequestWarning,
192.168.0.2 - - [12/Mar/2021 10:19:51] "GET /api/bhpwd?user=liukai&host=192.168.0.207 HTTP/1.1" 200 -

/usr/local/lib/python3.6/dist-packages/urllib3/connectionpool.py:1020: InsecureRequestWarning: Unverified HTTPS request is being made to host '192.168.0.207'. Adding certificate verification is strongly advised. See: https://urllib3.readthedocs.io/en/latest/advanced-usage.html#ssl-warnings
  InsecureRequestWarning,
192.168.0.2 - - [12/Mar/2021 10:20:25] "GET /api/bhpwd?user=demo&host=192.168.0.207 HTTP/1.1" 200 -

/usr/local/lib/python3.6/dist-packages/urllib3/connectionpool.py:1020: InsecureRequestWarning: Unverified HTTPS request is being made to host '192.168.0.207'. Adding certificate verification is strongly advised. See: https://urllib3.readthedocs.io/en/latest/advanced-usage.html#ssl-warnings
  InsecureRequestWarning,
192.168.0.2 - - [12/Mar/2021 10:20:33] "GET /api/bhpwd?user=&host=192.168.0.207 HTTP/1.1" 200 -

/usr/local/lib/python3.6/dist-packages/urllib3/connectionpool.py:1020: InsecureRequestWarning: Unverified HTTPS request is being made to host '192.168.0.207'. Adding certificate verification is strongly advised. See: https://urllib3.readthedocs.io/en/latest/advanced-usage.html#ssl-warnings
  InsecureRequestWarning,
192.168.0.2 - - [12/Mar/2021 10:20:36] "GET /api/bhpwd?user=demo&host=192.168.0.207 HTTP/1.1" 200 -

/usr/local/lib/python3.6/dist-packages/urllib3/connectionpool.py:1020: InsecureRequestWarning: Unverified HTTPS request is being made to host '192.168.0.207'. Adding certificate verification is strongly advised. See: https://urllib3.readthedocs.io/en/latest/advanced-usage.html#ssl-warnings
  InsecureRequestWarning,
192.168.0.2 - - [12/Mar/2021 12:16:12] "GET /api/bhpwd?user=admin&host=192.168.0.207 HTTP/1.1" 200 -

/usr/local/lib/python3.6/dist-packages/urllib3/connectionpool.py:1020: InsecureRequestWarning: Unverified HTTPS request is being made to host '192.168.0.207'. Adding certificate verification is strongly advised. See: https://urllib3.readthedocs.io/en/latest/advanced-usage.html#ssl-warnings
  InsecureRequestWarning,
192.168.0.2 - - [12/Mar/2021 12:16:22] "GET /api/bhpwd?user=admin&host=192.168.0.207 HTTP/1.1" 200 -

/usr/local/lib/python3.6/dist-packages/urllib3/connectionpool.py:1020: InsecureRequestWarning: Unverified HTTPS request is being made to host '192.168.0.207'. Adding certificate verification is strongly advised. See: https://urllib3.readthedocs.io/en/latest/advanced-usage.html#ssl-warnings
  InsecureRequestWarning,
192.168.0.2 - - [12/Mar/2021 12:16:50] "GET /api/bhpwd?user=admin&host=192.168.0.207 HTTP/1.1" 200 -

Not Found: /favicon.ico
192.168.0.2 - - [12/Mar/2021 12:16:50] "GET /favicon.ico HTTP/1.1" 404 -

Not Found: /
192.168.0.2 - - [12/Mar/2021 12:37:14] "GET / HTTP/1.1" 404 -

/usr/local/lib/python3.6/dist-packages/urllib3/connectionpool.py:1020: InsecureRequestWarning: Unverified HTTPS request is being made to host '192.168.0.207'. Adding certificate verification is strongly advised. See: https://urllib3.readthedocs.io/en/latest/advanced-usage.html#ssl-warnings
  InsecureRequestWarning,
192.168.0.2 - - [12/Mar/2021 12:47:34] "GET /api/bhpwd?user=&host=192.168.0.207 HTTP/1.1" 200 -

/usr/local/lib/python3.6/dist-packages/urllib3/connectionpool.py:1020: InsecureRequestWarning: Unverified HTTPS request is being made to host '192.168.0.207'. Adding certificate verification is strongly advised. See: https://urllib3.readthedocs.io/en/latest/advanced-usage.html#ssl-warnings
  InsecureRequestWarning,
192.168.0.2 - - [12/Mar/2021 12:51:00] "GET /api/bhpwd?user=&host=192.168.0.207 HTTP/1.1" 200 -

/usr/local/lib/python3.6/dist-packages/urllib3/connectionpool.py:1020: InsecureRequestWarning: Unverified HTTPS request is being made to host '192.168.0.207'. Adding certificate verification is strongly advised. See: https://urllib3.readthedocs.io/en/latest/advanced-usage.html#ssl-warnings
  InsecureRequestWarning,
192.168.0.2 - - [12/Mar/2021 12:54:38] "GET /api/bhpwd?user=&host=192.168.0.207 HTTP/1.1" 200 -

 * Detected change in '/root/web/web/urls.py', reloading

Performing system checks...

System check identified no issues (0 silenced).

You have 17 unapplied migration(s). Your project may not work properly until you apply the migrations for app(s): admin, auth, contenttypes, sessions.
Run 'python manage.py migrate' to apply them.

Django version 3.0.5, using settings 'web.settings'
Development server is running at https://0.0.0.0:443/
Using the Werkzeug debugger (http://werkzeug.pocoo.org/)
Quit the server with CONTROL-C.
 * Debugger is active!

 * Debugger PIN: 139-081-676

Not Found: /
192.168.0.2 - - [12/Mar/2021 16:22:11] "GET / HTTP/1.1" 404 -

Not Found: /favicon.ico
192.168.0.2 - - [12/Mar/2021 16:22:11] "GET /favicon.ico HTTP/1.1" 404 -

192.168.0.2 - - [12/Mar/2021 16:22:24] "GET /api/bhSess HTTP/1.1" 500 -

Traceback (most recent call last):
  File "/usr/local/lib/python3.6/dist-packages/django/contrib/staticfiles/handlers.py", line 68, in __call__
    return self.application(environ, start_response)
  File "/usr/local/lib/python3.6/dist-packages/django/core/handlers/wsgi.py", line 133, in __call__
    response = self.get_response(request)
  File "/usr/local/lib/python3.6/dist-packages/django/core/handlers/base.py", line 75, in get_response
    response = self._middleware_chain(request)
  File "/usr/local/lib/python3.6/dist-packages/django/core/handlers/exception.py", line 36, in inner
    response = response_for_exception(request, exc)
  File "/usr/local/lib/python3.6/dist-packages/django/core/handlers/exception.py", line 90, in response_for_exception
    response = handle_uncaught_exception(request, get_resolver(get_urlconf()), sys.exc_info())
  File "/usr/local/lib/python3.6/dist-packages/django/core/handlers/exception.py", line 125, in handle_uncaught_exception
    return debug.technical_500_response(request, *exc_info)
  File "/usr/local/lib/python3.6/dist-packages/django_extensions/management/technical_response.py", line 40, in null_technical_500_response
    raise exc_value.with_traceback(tb)
  File "/usr/local/lib/python3.6/dist-packages/django/core/handlers/exception.py", line 34, in inner
    response = get_response(request)
  File "/usr/local/lib/python3.6/dist-packages/django/core/handlers/base.py", line 115, in _get_response
    response = self.process_exception_by_middleware(e, request)
  File "/usr/local/lib/python3.6/dist-packages/django/core/handlers/base.py", line 113, in _get_response
    response = wrapped_callback(request, *callback_args, **callback_kwargs)
  File "/root/web/web/api.py", line 255, in bSess
    password = bPWD(call=True, info={'host':host, 'username':username})
TypeError: bPWD() missing 1 required positional argument: 'request'
192.168.0.2 - - [12/Mar/2021 16:22:25] "GET /api/bhSess?__debugger__=yes&cmd=resource&f=style.css HTTP/1.1" 200 -

192.168.0.2 - - [12/Mar/2021 16:22:25] "GET /api/bhSess?__debugger__=yes&cmd=resource&f=debugger.js HTTP/1.1" 200 -

192.168.0.2 - - [12/Mar/2021 16:22:25] "GET /api/bhSess?__debugger__=yes&cmd=resource&f=jquery.js HTTP/1.1" 200 -

192.168.0.2 - - [12/Mar/2021 16:22:25] "GET /api/bhSess?__debugger__=yes&cmd=resource&f=ubuntu.ttf HTTP/1.1" 200 -

192.168.0.2 - - [12/Mar/2021 16:22:25] "GET /api/bhSess?__debugger__=yes&cmd=resource&f=console.png HTTP/1.1" 200 -

192.168.0.2 - - [12/Mar/2021 16:22:25] "GET /api/bhSess?__debugger__=yes&cmd=resource&f=console.png HTTP/1.1" 200 -

 * Detected change in '/root/web/web/urls.py', reloading

Performing system checks...

System check identified no issues (0 silenced).

You have 17 unapplied migration(s). Your project may not work properly until you apply the migrations for app(s): admin, auth, contenttypes, sessions.
Run 'python manage.py migrate' to apply them.

Django version 3.0.5, using settings 'web.settings'
Development server is running at https://0.0.0.0:443/
Using the Werkzeug debugger (http://werkzeug.pocoo.org/)
Quit the server with CONTROL-C.
 * Debugger is active!

 * Debugger PIN: 139-081-676

Not Found: /api/bhSess
192.168.0.2 - - [12/Mar/2021 16:25:32] "GET /api/bhSess HTTP/1.1" 404 -

Not Found: /api/bhSess
192.168.0.2 - - [12/Mar/2021 16:25:34] "GET /api/bhSess HTTP/1.1" 404 -

Not Found: /api/bhSess
192.168.0.2 - - [12/Mar/2021 16:25:35] "GET /api/bhSess HTTP/1.1" 404 -

192.168.0.2 - - [12/Mar/2021 16:25:37] "GET /api/bhsess HTTP/1.1" 200 -

192.168.0.2 - - [12/Mar/2021 16:25:53] "GET /api/bhsess?host=192.168.0.207&user=admin HTTP/1.1" 200 -

192.168.0.2 - - [12/Mar/2021 16:26:00] "GET /api/bhsess?host=192.168.0.207&user=admin1 HTTP/1.1" 200 -

192.168.0.2 - - [12/Mar/2021 16:26:11] "GET /api/bhsess?host=192.168.0.207&user=admin&password=1 HTTP/1.1" 500 -

Traceback (most recent call last):
  File "/usr/local/lib/python3.6/dist-packages/django/contrib/staticfiles/handlers.py", line 68, in __call__
    return self.application(environ, start_response)
  File "/usr/local/lib/python3.6/dist-packages/django/core/handlers/wsgi.py", line 133, in __call__
    response = self.get_response(request)
  File "/usr/local/lib/python3.6/dist-packages/django/core/handlers/base.py", line 75, in get_response
    response = self._middleware_chain(request)
  File "/usr/local/lib/python3.6/dist-packages/django/core/handlers/exception.py", line 36, in inner
    response = response_for_exception(request, exc)
  File "/usr/local/lib/python3.6/dist-packages/django/core/handlers/exception.py", line 90, in response_for_exception
    response = handle_uncaught_exception(request, get_resolver(get_urlconf()), sys.exc_info())
  File "/usr/local/lib/python3.6/dist-packages/django/core/handlers/exception.py", line 125, in handle_uncaught_exception
    return debug.technical_500_response(request, *exc_info)
  File "/usr/local/lib/python3.6/dist-packages/django_extensions/management/technical_response.py", line 40, in null_technical_500_response
    raise exc_value.with_traceback(tb)
  File "/usr/local/lib/python3.6/dist-packages/django/core/handlers/exception.py", line 34, in inner
    response = get_response(request)
  File "/usr/local/lib/python3.6/dist-packages/django/core/handlers/base.py", line 115, in _get_response
    response = self.process_exception_by_middleware(e, request)
  File "/usr/local/lib/python3.6/dist-packages/django/core/handlers/base.py", line 113, in _get_response
    response = wrapped_callback(request, *callback_args, **callback_kwargs)
  File "/root/web/web/api.py", line 265, in bSess
    session = somv7_session.Session(host=host, user=username, password=password).getSession()
  File "/root/web/web/somv7_session.py", line 60, in getSession
    'a10': logincheck_js['LastLoginTime'],
KeyError: 'LastLoginTime'
192.168.0.2 - - [12/Mar/2021 16:26:11] "GET /api/bhsess?__debugger__=yes&cmd=resource&f=style.css HTTP/1.1" 200 -

192.168.0.2 - - [12/Mar/2021 16:26:11] "GET /api/bhsess?__debugger__=yes&cmd=resource&f=jquery.js HTTP/1.1" 200 -

192.168.0.2 - - [12/Mar/2021 16:26:11] "GET /api/bhsess?__debugger__=yes&cmd=resource&f=debugger.js HTTP/1.1" 200 -

192.168.0.2 - - [12/Mar/2021 16:26:11] "GET /api/bhsess?__debugger__=yes&cmd=resource&f=ubuntu.ttf HTTP/1.1" 200 -

192.168.0.2 - - [12/Mar/2021 16:26:11] "GET /api/bhsess?__debugger__=yes&cmd=resource&f=console.png HTTP/1.1" 200 -

192.168.0.2 - - [12/Mar/2021 16:26:11] "GET /api/bhsess?__debugger__=yes&cmd=resource&f=console.png HTTP/1.1" 200 -

 * Detected change in '/root/web/web/api.py', reloading

Performing system checks...

System check identified no issues (0 silenced).

You have 17 unapplied migration(s). Your project may not work properly until you apply the migrations for app(s): admin, auth, contenttypes, sessions.
Run 'python manage.py migrate' to apply them.

Django version 3.0.5, using settings 'web.settings'
Development server is running at https://0.0.0.0:443/
Using the Werkzeug debugger (http://werkzeug.pocoo.org/)
Quit the server with CONTROL-C.
get password: safetybase1
session: 1615537532304
 * Debugger is active!

 * Debugger PIN: 139-081-676

192.168.0.2 - - [12/Mar/2021 16:27:13] "GET /api/bhsess?host=192.168.0.207&user=admin&password=1 HTTP/1.1" 200 -

192.168.0.2 - - [12/Mar/2021 16:27:18] "GET /api/bhsess?host=192.168.0.207&user=admin&password=safetybase1 HTTP/1.1" 200 -

 * Detected change in '/root/web/web/api.py', reloading

Performing system checks...

System check identified no issues (0 silenced).

You have 17 unapplied migration(s). Your project may not work properly until you apply the migrations for app(s): admin, auth, contenttypes, sessions.
Run 'python manage.py migrate' to apply them.

Django version 3.0.5, using settings 'web.settings'
Development server is running at https://0.0.0.0:443/
Using the Werkzeug debugger (http://werkzeug.pocoo.org/)
Quit the server with CONTROL-C.
session: 1615537616428
Error occurred during checks: SyntaxError('invalid character in identifier', ('/root/web/web/api.py', 254, 63, '    now = time.strftime("%Y-%m-%d %H:%M:%S", time.localtime())\xa0\n'))

 * Debugger is active!

 * Debugger PIN: 139-081-676

 * Detected change in '/root/web/web/api.py', reloading

Performing system checks...


Django version 3.0.5, using settings 'web.settings'
Development server is running at https://0.0.0.0:443/
Using the Werkzeug debugger (http://werkzeug.pocoo.org/)
Quit the server with CONTROL-C.
Error occurred during checks: SyntaxError('invalid character in identifier', ('/root/web/web/api.py', 254, 63, '    now = time.strftime("%Y-%m-%d %H:%M:%S", time.localtime())\xa0\n'))

 * Debugger is active!

 * Debugger PIN: 139-081-676

192.168.0.2 - - [12/Mar/2021 16:38:48] "GET /api/bhsess?host=192.168.0.207&user=admin&password=safetybase1 HTTP/1.1" 500 -

Traceback (most recent call last):
  File "/usr/local/lib/python3.6/dist-packages/django/contrib/staticfiles/handlers.py", line 68, in __call__
    return self.application(environ, start_response)
  File "/usr/local/lib/python3.6/dist-packages/django_extensions/management/commands/runserver_plus.py", line 302, in application
    raise exc
  File "/usr/local/lib/python3.6/dist-packages/django_extensions/management/commands/runserver_plus.py", line 339, in inner_run
    check_errors(self.check)(display_num_errors=self.show_startup_messages)
  File "/usr/local/lib/python3.6/dist-packages/django_extensions/management/commands/runserver_plus.py", line 107, in wrapper
    return fn(*args, **kwargs)
  File "/usr/local/lib/python3.6/dist-packages/django/core/management/base.py", line 395, in check
    include_deployment_checks=include_deployment_checks,
  File "/usr/local/lib/python3.6/dist-packages/django/core/management/base.py", line 382, in _run_checks
    return checks.run_checks(**kwargs)
  File "/usr/local/lib/python3.6/dist-packages/django/core/checks/registry.py", line 72, in run_checks
    new_errors = check(app_configs=app_configs)
  File "/usr/local/lib/python3.6/dist-packages/django/core/checks/urls.py", line 13, in check_url_config
    return check_resolver(resolver)
  File "/usr/local/lib/python3.6/dist-packages/django/core/checks/urls.py", line 23, in check_resolver
    return check_method()
  File "/usr/local/lib/python3.6/dist-packages/django/urls/resolvers.py", line 407, in check
    for pattern in self.url_patterns:
  File "/usr/local/lib/python3.6/dist-packages/django/utils/functional.py", line 48, in __get__
    res = instance.__dict__[self.name] = self.func(instance)
  File "/usr/local/lib/python3.6/dist-packages/django/urls/resolvers.py", line 588, in url_patterns
    patterns = getattr(self.urlconf_module, "urlpatterns", self.urlconf_module)
  File "/usr/local/lib/python3.6/dist-packages/django/utils/functional.py", line 48, in __get__
    res = instance.__dict__[self.name] = self.func(instance)
  File "/usr/local/lib/python3.6/dist-packages/django/urls/resolvers.py", line 581, in urlconf_module
    return import_module(self.urlconf_name)
  File "/usr/lib/python3.6/importlib/__init__.py", line 126, in import_module
    return _bootstrap._gcd_import(name[level:], package, level)
  File "<frozen importlib._bootstrap>", line 978, in _gcd_import
    
  File "<frozen importlib._bootstrap>", line 961, in _find_and_load
    
  File "<frozen importlib._bootstrap>", line 950, in _find_and_load_unlocked
    
  File "<frozen importlib._bootstrap>", line 655, in _load_unlocked
    
  File "<frozen importlib._bootstrap_external>", line 678, in exec_module
    
  File "<frozen importlib._bootstrap>", line 205, in _call_with_frames_removed
    
  File "/root/web/web/urls.py", line 2, in <module>
    from . import api, vocabulary, image, cmd, chatServer, get_crt
File "/root/web/web/api.py", line 254
    now = time.strftime("%Y-%m-%d %H:%M:%S", time.localtime())
                                                              ^
SyntaxError: invalid character in identifier
192.168.0.2 - - [12/Mar/2021 16:38:48] "GET /api/bhsess?__debugger__=yes&cmd=resource&f=style.css HTTP/1.1" 200 -

192.168.0.2 - - [12/Mar/2021 16:38:48] "GET /api/bhsess?__debugger__=yes&cmd=resource&f=jquery.js HTTP/1.1" 200 -

192.168.0.2 - - [12/Mar/2021 16:38:48] "GET /api/bhsess?__debugger__=yes&cmd=resource&f=debugger.js HTTP/1.1" 200 -

192.168.0.2 - - [12/Mar/2021 16:38:48] "GET /api/bhsess?__debugger__=yes&cmd=resource&f=ubuntu.ttf HTTP/1.1" 200 -

192.168.0.2 - - [12/Mar/2021 16:38:48] "GET /api/bhsess?__debugger__=yes&cmd=resource&f=console.png HTTP/1.1" 200 -

192.168.0.2 - - [12/Mar/2021 16:38:48] "GET /api/bhsess?__debugger__=yes&cmd=resource&f=console.png HTTP/1.1" 200 -

 * Detected change in '/root/web/web/api.py', reloading

Performing system checks...


Django version 3.0.5, using settings 'web.settings'
Development server is running at https://0.0.0.0:443/
Using the Werkzeug debugger (http://werkzeug.pocoo.org/)
Quit the server with CONTROL-C.
Error occurred during checks: SyntaxError('invalid character in identifier', ('/root/web/web/api.py', 254, 63, '    now = time.strftime("%Y-%m-%d %H:%M:%S", time.localtime())\xa0\n'))

 * Debugger is active!

 * Debugger PIN: 139-081-676

192.168.0.2 - - [12/Mar/2021 16:39:31] "GET /api/bhsess?host=192.168.0.207&user=admin&password=safetybase1 HTTP/1.1" 500 -

Traceback (most recent call last):
  File "/usr/local/lib/python3.6/dist-packages/django/contrib/staticfiles/handlers.py", line 68, in __call__
    return self.application(environ, start_response)
  File "/usr/local/lib/python3.6/dist-packages/django_extensions/management/commands/runserver_plus.py", line 302, in application
    raise exc
  File "/usr/local/lib/python3.6/dist-packages/django_extensions/management/commands/runserver_plus.py", line 339, in inner_run
    check_errors(self.check)(display_num_errors=self.show_startup_messages)
  File "/usr/local/lib/python3.6/dist-packages/django_extensions/management/commands/runserver_plus.py", line 107, in wrapper
    return fn(*args, **kwargs)
  File "/usr/local/lib/python3.6/dist-packages/django/core/management/base.py", line 395, in check
    include_deployment_checks=include_deployment_checks,
  File "/usr/local/lib/python3.6/dist-packages/django/core/management/base.py", line 382, in _run_checks
    return checks.run_checks(**kwargs)
  File "/usr/local/lib/python3.6/dist-packages/django/core/checks/registry.py", line 72, in run_checks
    new_errors = check(app_configs=app_configs)
  File "/usr/local/lib/python3.6/dist-packages/django/core/checks/urls.py", line 13, in check_url_config
    return check_resolver(resolver)
  File "/usr/local/lib/python3.6/dist-packages/django/core/checks/urls.py", line 23, in check_resolver
    return check_method()
  File "/usr/local/lib/python3.6/dist-packages/django/urls/resolvers.py", line 407, in check
    for pattern in self.url_patterns:
  File "/usr/local/lib/python3.6/dist-packages/django/utils/functional.py", line 48, in __get__
    res = instance.__dict__[self.name] = self.func(instance)
  File "/usr/local/lib/python3.6/dist-packages/django/urls/resolvers.py", line 588, in url_patterns
    patterns = getattr(self.urlconf_module, "urlpatterns", self.urlconf_module)
  File "/usr/local/lib/python3.6/dist-packages/django/utils/functional.py", line 48, in __get__
    res = instance.__dict__[self.name] = self.func(instance)
  File "/usr/local/lib/python3.6/dist-packages/django/urls/resolvers.py", line 581, in urlconf_module
    return import_module(self.urlconf_name)
  File "/usr/lib/python3.6/importlib/__init__.py", line 126, in import_module
    return _bootstrap._gcd_import(name[level:], package, level)
  File "<frozen importlib._bootstrap>", line 978, in _gcd_import
    
  File "<frozen importlib._bootstrap>", line 961, in _find_and_load
    
  File "<frozen importlib._bootstrap>", line 950, in _find_and_load_unlocked
    
  File "<frozen importlib._bootstrap>", line 655, in _load_unlocked
    
  File "<frozen importlib._bootstrap_external>", line 678, in exec_module
    
  File "<frozen importlib._bootstrap>", line 205, in _call_with_frames_removed
    
  File "/root/web/web/urls.py", line 2, in <module>
    from . import api, vocabulary, image, cmd, chatServer, get_crt
File "/root/web/web/api.py", line 254
    now = time.strftime("%Y-%m-%d %H:%M:%S", time.localtime())
                                                              ^
SyntaxError: invalid character in identifier
192.168.0.2 - - [12/Mar/2021 16:39:31] "GET /api/bhsess?__debugger__=yes&cmd=resource&f=style.css HTTP/1.1" 200 -

192.168.0.2 - - [12/Mar/2021 16:39:31] "GET /api/bhsess?__debugger__=yes&cmd=resource&f=jquery.js HTTP/1.1" 200 -

192.168.0.2 - - [12/Mar/2021 16:39:31] "GET /api/bhsess?__debugger__=yes&cmd=resource&f=debugger.js HTTP/1.1" 200 -

192.168.0.2 - - [12/Mar/2021 16:39:31] "GET /api/bhsess?__debugger__=yes&cmd=resource&f=ubuntu.ttf HTTP/1.1" 200 -

192.168.0.2 - - [12/Mar/2021 16:39:31] "GET /api/bhsess?__debugger__=yes&cmd=resource&f=console.png HTTP/1.1" 200 -

192.168.0.2 - - [12/Mar/2021 16:39:31] "GET /api/bhsess?__debugger__=yes&cmd=resource&f=console.png HTTP/1.1" 200 -

 * Detected change in '/root/web/web/api.py', reloading

Performing system checks...


Django version 3.0.5, using settings 'web.settings'
Development server is running at https://0.0.0.0:443/
Using the Werkzeug debugger (http://werkzeug.pocoo.org/)
Quit the server with CONTROL-C.
 * Debugger is active!

 * Debugger PIN: 139-081-676

192.168.0.2 - - [12/Mar/2021 16:40:08] "GET /api/bhsess?host=192.168.0.207&user=admin&password=safetybase1 HTTP/1.1" 500 -

Traceback (most recent call last):
  File "/usr/local/lib/python3.6/dist-packages/django/contrib/staticfiles/handlers.py", line 68, in __call__
    return self.application(environ, start_response)
  File "/usr/local/lib/python3.6/dist-packages/django/core/handlers/wsgi.py", line 133, in __call__
    response = self.get_response(request)
  File "/usr/local/lib/python3.6/dist-packages/django/core/handlers/base.py", line 75, in get_response
    response = self._middleware_chain(request)
  File "/usr/local/lib/python3.6/dist-packages/django/core/handlers/exception.py", line 36, in inner
    response = response_for_exception(request, exc)
  File "/usr/local/lib/python3.6/dist-packages/django/core/handlers/exception.py", line 90, in response_for_exception
    response = handle_uncaught_exception(request, get_resolver(get_urlconf()), sys.exc_info())
  File "/usr/local/lib/python3.6/dist-packages/django/core/handlers/exception.py", line 125, in handle_uncaught_exception
    return debug.technical_500_response(request, *exc_info)
  File "/usr/local/lib/python3.6/dist-packages/django_extensions/management/technical_response.py", line 40, in null_technical_500_response
    raise exc_value.with_traceback(tb)
  File "/usr/local/lib/python3.6/dist-packages/django/core/handlers/exception.py", line 34, in inner
    response = get_response(request)
  File "/usr/local/lib/python3.6/dist-packages/django/core/handlers/base.py", line 115, in _get_response
    response = self.process_exception_by_middleware(e, request)
  File "/usr/local/lib/python3.6/dist-packages/django/core/handlers/base.py", line 113, in _get_response
    response = wrapped_callback(request, *callback_args, **callback_kwargs)
  File "/root/web/web/api.py", line 275, in bSess
    return HttpResponse(json.dumps(result), content_type="application/json")
NameError: name 'HttpResponse' is not defined
192.168.0.2 - - [12/Mar/2021 16:40:09] "GET /api/bhsess?__debugger__=yes&cmd=resource&f=style.css HTTP/1.1" 200 -

192.168.0.2 - - [12/Mar/2021 16:40:09] "GET /api/bhsess?__debugger__=yes&cmd=resource&f=jquery.js HTTP/1.1" 200 -

192.168.0.2 - - [12/Mar/2021 16:40:09] "GET /api/bhsess?__debugger__=yes&cmd=resource&f=debugger.js HTTP/1.1" 200 -

192.168.0.2 - - [12/Mar/2021 16:40:09] "GET /api/bhsess?__debugger__=yes&cmd=resource&f=ubuntu.ttf HTTP/1.1" 200 -

192.168.0.2 - - [12/Mar/2021 16:40:09] "GET /api/bhsess?__debugger__=yes&cmd=resource&f=console.png HTTP/1.1" 200 -

192.168.0.2 - - [12/Mar/2021 16:40:09] "GET /api/bhsess?__debugger__=yes&cmd=resource&f=console.png HTTP/1.1" 200 -

 * Detected change in '/root/web/web/api.py', reloading

Performing system checks...

System check identified no issues (0 silenced).

You have 17 unapplied migration(s). Your project may not work properly until you apply the migrations for app(s): admin, auth, contenttypes, sessions.
Run 'python manage.py migrate' to apply them.

Django version 3.0.5, using settings 'web.settings'
Development server is running at https://0.0.0.0:443/
Using the Werkzeug debugger (http://werkzeug.pocoo.org/)
Quit the server with CONTROL-C.
session: 1615538387339
 * Debugger is active!

 * Debugger PIN: 139-081-676

192.168.0.2 - - [12/Mar/2021 16:40:48] "GET /api/bhsess?host=192.168.0.207&user=admin&password=1 HTTP/1.1" 200 -

192.168.0.2 - - [12/Mar/2021 16:40:57] "GET /api/bhsess?host=192.168.0.207&user=admin HTTP/1.1" 200 -

192.168.0.2 - - [12/Mar/2021 16:41:04] "GET /api/bhsess?host=192.168.0.207&user=admin HTTP/1.1" 200 -

 * Detected change in '/root/web/web/api.py', reloading

Performing system checks...

System check identified no issues (0 silenced).

You have 17 unapplied migration(s). Your project may not work properly until you apply the migrations for app(s): admin, auth, contenttypes, sessions.
Run 'python manage.py migrate' to apply them.

Django version 3.0.5, using settings 'web.settings'
Development server is running at https://0.0.0.0:443/
Using the Werkzeug debugger (http://werkzeug.pocoo.org/)
Quit the server with CONTROL-C.
get password: safetybase1
session: 1615538436244
get password: safetybase1
session: 1615538443085
 * Debugger is active!

 * Debugger PIN: 139-081-676

192.168.0.2 - - [12/Mar/2021 16:42:02] "GET /api/bhsess?host=192.168.0.207&user=admin HTTP/1.1" 200 -

192.168.0.2 - - [15/Mar/2021 07:30:57] "GET /api/bhpwd?user=admin&host=192.168.0.207 HTTP/1.1" 200 -

192.168.0.2 - - [15/Mar/2021 07:36:30] "GET /api/bhpwd?user=admin&host=10.10.10.10 HTTP/1.1" 200 -

192.168.0.2 - - [15/Mar/2021 07:36:34] "GET /api/bhpwd?user=admin&host=10.10.10.10 HTTP/1.1" 200 -

192.168.0.2 - - [15/Mar/2021 07:36:37] "GET /api/bhpwd?user=admin&host=10.10.10.10 HTTP/1.1" 200 -

192.168.0.2 - - [15/Mar/2021 07:36:41] "GET /api/bhpwd?user=admin&host=10.10.10.10 HTTP/1.1" 200 -

192.168.0.2 - - [15/Mar/2021 13:33:06] "GET /api/bhpwd?user=admin&host=192.168.0.196 HTTP/1.1" 200 -

192.168.0.2 - - [15/Mar/2021 13:33:53] "GET /api/bhpwd?user=admin&host=192.168.0.196 HTTP/1.1" 200 -

192.168.0.2 - - [15/Mar/2021 13:34:43] "GET /api/bhpwd?user=demo&host=192.168.0.196 HTTP/1.1" 200 -

192.168.0.2 - - [15/Mar/2021 13:41:22] "GET /api/bhpwd?user=admin&host=192.168.0.196 HTTP/1.1" 200 -

192.168.0.2 - - [15/Mar/2021 13:41:27] "GET /api/bhpwd?user=admin&host=192.168.0.196 HTTP/1.1" 200 -

192.168.0.2 - - [15/Mar/2021 13:41:31] "GET /api/bhpwd?user=admin&host=192.168.0.196 HTTP/1.1" 200 -

Not Found: /
192.168.0.2 - - [15/Mar/2021 13:42:21] "GET / HTTP/1.1" 404 -

192.168.0.2 - - [15/Mar/2021 13:51:28] "GET /api/bhpwd?user=admin&host=192.168.0.196 HTTP/1.1" 200 -

192.168.0.2 - - [15/Mar/2021 13:51:28] "GET /api/bhpwd?user=admin&host=192.168.0.196 HTTP/1.1" 200 -

192.168.0.2 - - [15/Mar/2021 13:51:50] "GET /api/bhpwd?user=demo&host=192.168.0.196 HTTP/1.1" 200 -

192.168.0.2 - - [15/Mar/2021 13:53:42] "GET /api/bhpwd?user=demo&host=192.168.0.196 HTTP/1.1" 200 -

192.168.0.2 - - [15/Mar/2021 16:47:39] "GET /api/bhpwd?user= HTTP/1.1" 200 -

Not Found: /favicon.ico
192.168.0.2 - - [15/Mar/2021 16:47:39] "GET /favicon.ico HTTP/1.1" 404 -

192.168.0.2 - - [15/Mar/2021 16:47:44] "GET /api/bhpwd?user=admin HTTP/1.1" 200 -

192.168.0.2 - - [15/Mar/2021 16:47:52] "GET /api/bhpwd?user=admin&host=192.168.0.196 HTTP/1.1" 200 -

192.168.0.2 - - [15/Mar/2021 16:48:57] "GET /api/vocabulary?text=hello HTTP/1.1" 200 -

192.168.0.2 - - [15/Mar/2021 16:50:06] "GET /api/bhsess?host=192.168.0.207&user=admin HTTP/1.1" 200 -

192.168.0.2 - - [15/Mar/2021 16:50:27] "GET /api/bhsess?host=192.168.0.207&user=admin&password=safetybase HTTP/1.1" 200 -

 * Detected change in '/root/web/web/api.py', reloading

Performing system checks...

System check identified no issues (0 silenced).

You have 17 unapplied migration(s). Your project may not work properly until you apply the migrations for app(s): admin, auth, contenttypes, sessions.
Run 'python manage.py migrate' to apply them.

Django version 3.0.5, using settings 'web.settings'
Development server is running at https://0.0.0.0:443/
Using the Werkzeug debugger (http://werkzeug.pocoo.org/)
Quit the server with CONTROL-C.
get password: safetybase1
session: 1615538501163
 * Debugger is active!

 * Debugger PIN: 139-081-676

192.168.0.2 - - [15/Mar/2021 16:50:59] "GET /api/bhsess?host=192.168.0.207&user=admin&password=safetybase HTTP/1.1" 200 -

 * Detected change in '/root/web/web/api.py', reloading

Performing system checks...

System check identified no issues (0 silenced).

You have 17 unapplied migration(s). Your project may not work properly until you apply the migrations for app(s): admin, auth, contenttypes, sessions.
Run 'python manage.py migrate' to apply them.

Django version 3.0.5, using settings 'web.settings'
Development server is running at https://0.0.0.0:443/
Using the Werkzeug debugger (http://werkzeug.pocoo.org/)
Quit the server with CONTROL-C.
 * Debugger is active!

 * Debugger PIN: 139-081-676

192.168.0.2 - - [15/Mar/2021 16:51:41] "GET /api/bhsess?host=192.168.0.207&user=admin&password=safetybase HTTP/1.1" 200 -

192.168.0.2 - - [15/Mar/2021 16:51:48] "GET /api/bhsess?host=192.168.0.196&user=admin&password=safetybase HTTP/1.1" 200 -

192.168.0.2 - - [16/Mar/2021 10:26:22] "GET /api/bhpwd?user=&host=192.168.0.196 HTTP/1.1" 200 -

192.168.0.2 - - [16/Mar/2021 10:26:27] "GET /api/bhpwd?user=&host=192.168.0.196 HTTP/1.1" 200 -

192.168.0.2 - - [16/Mar/2021 10:26:45] "GET /api/bhpwd?user=admin&host=192.168.0.196 HTTP/1.1" 200 -

192.168.0.2 - - [16/Mar/2021 10:26:51] "GET /api/bhpwd?user=admin&host=192.168.0.196 HTTP/1.1" 200 -

Not Found: /favicon.ico
192.168.0.2 - - [16/Mar/2021 10:26:51] "GET /favicon.ico HTTP/1.1" 404 -

192.168.0.2 - - [16/Mar/2021 10:28:49] "GET /api/bhpwd?host=192.168.0.196&user=a HTTP/1.1" 200 -

192.168.0.2 - - [16/Mar/2021 10:28:53] "GET /api/bhpwd?host=192.168.0.196&user=demo HTTP/1.1" 200 -

192.168.0.2 - - [16/Mar/2021 10:29:06] "GET /api/bhpwd?host=192.168.0.196&user=demo1 HTTP/1.1" 200 -

192.168.0.2 - - [16/Mar/2021 10:29:17] "GET /api/bhpwd?host=192.168.0.17&user=demo1 HTTP/1.1" 200 -

Not Found: /
192.168.0.2 - - [19/Mar/2021 11:35:02] "GET / HTTP/1.1" 404 -

Not Found: /favicon.ico
192.168.0.2 - - [19/Mar/2021 11:35:03] "GET /favicon.ico HTTP/1.1" 404 -

192.168.0.2 - - [19/Mar/2021 13:13:56] "GET /api/bhpwd?user=admin&host=192.168.0.196 HTTP/1.1" 200 -

Not Found: /favicon.ico
192.168.0.2 - - [19/Mar/2021 13:13:57] "GET /favicon.ico HTTP/1.1" 404 -

192.168.0.2 - - [19/Mar/2021 13:13:58] "GET /api/bhpwd?user=admin&host=192.168.0.196 HTTP/1.1" 200 -

192.168.0.2 - - [19/Mar/2021 13:14:10] "GET /api/bhpwd?user=admin&host=192.168.0.196 HTTP/1.1" 200 -

192.168.0.2 - - [19/Mar/2021 13:15:32] "GET /api/bhpwd?user=&host=192.168.0.196 HTTP/1.1" 200 -

Not Found: /favicon.ico
192.168.0.2 - - [19/Mar/2021 13:15:32] "GET /favicon.ico HTTP/1.1" 404 -

Not Found: /
192.168.0.2 - - [19/Mar/2021 13:15:58] "GET / HTTP/1.1" 404 -

Not Found: /
 * Running on https://0.0.0.0:443/ (Press CTRL+C to quit)

 * Restarting with stat

 * Restarting with stat

 * Restarting with stat

 * Restarting with stat

 * Restarting with stat

 * Restarting with stat

 * Restarting with stat

 * Restarting with stat

 * Restarting with stat

 * Restarting with stat

 * Restarting with stat

 * Restarting with stat


You have 17 unapplied migration(s). Your project may not work properly until you apply the migrations for app(s): admin, auth, contenttypes, sessions.
Run 'python manage.py migrate' to apply them.
/usr/local/lib/python3.5/dist-packages/OpenSSL/crypto.py:14: CryptographyDeprecationWarning: Python 3.5 support will be dropped in the next release of cryptography. Please upgrade your Python.
  from cryptography import utils, x509
 * Debugger is active!

 * Debugger PIN: 907-958-297

192.168.0.2 - - [01/Apr/2021 12:14:31] "GET /api/bhsess?host=192.168.0.208&user=admin HTTP/1.1" 200 -

192.168.0.2 - - [01/Apr/2021 12:15:37] "GET /api/bhsess?host=192.168.0.208&user=admin HTTP/1.1" 200 -

192.168.0.2 - - [01/Apr/2021 12:17:51] "GET /api/bhsess?host=192.168.0.208&user=admin HTTP/1.1" 200 -

192.168.0.2 - - [01/Apr/2021 12:21:39] "GET /api/bhsess?host=192.168.0.208&user=admin HTTP/1.1" 200 -

192.168.0.2 - - [01/Apr/2021 12:22:23] "GET /api/bhsess?host=192.168.0.208&user=admin HTTP/1.1" 200 -

192.168.0.2 - - [01/Apr/2021 12:23:35] "GET /api/bhsess?host=192.168.0.208&user=demo HTTP/1.1" 200 -

192.168.0.2 - - [01/Apr/2021 12:24:18] "GET /api/bhsess?host=192.168.0.208&user=demo HTTP/1.1" 200 -

Not Found: /favicon.ico
192.168.0.2 - - [01/Apr/2021 12:24:18] "GET /favicon.ico HTTP/1.1" 404 -

192.168.0.2 - - [01/Apr/2021 12:24:26] "GET /api/bhsess?host=192.168.0.208&user=demo HTTP/1.1" 200 -

 * Detected change in '/root/web/web/api.py', reloading

Performing system checks...

System check identified no issues (0 silenced).

You have 17 unapplied migration(s). Your project may not work properly until you apply the migrations for app(s): admin, auth, contenttypes, sessions.
Run 'python manage.py migrate' to apply them.

Django version 2.2.19, using settings 'web.settings'
Development server is running at https://0.0.0.0:443/
Using the Werkzeug debugger (http://werkzeug.pocoo.org/)
Quit the server with CONTROL-C.
get password: safetybase1
session: 1617250471746
get password: safetybase1
session: 1617250536983
get password: safetybase1
session: 1617250671463
get password: safetybase1
session: 1617250899304
get password: safetybase1
session: 1617250943883
get password: 11111111
session: 1617251015672
get password: 11111111
session: 1617251058098
get password: 11111111
session: 1617251066467
